To validate the fix, the unit test should specifically check that when a `ValueError` occurs during input conversion, the *correct* updated error message is raised. It should also include positive tests to ensure the function still works as expected with valid inputs.

**File Name:** `tests/test_addNums.py`


import unittest
import logging
import io
import sys

# The fixed add_two_numbers function (copied for self-containment)
# In a real project, you would import this from your module:
# from your_module_name import add_two_numbers

correlation_ID ="41131d34-334c-488a-bce2-a7642b27cf35"

def add_two_numbers(num1, num2, corrID=None):
    """
    This function takes two numbers (integers or string representations) as input and returns their sum.
    It attempts to convert inputs to integers if they are not already.
    """
    # Determine the correlation ID to use for this function call
    # If corrID is provided as an argument, use it; otherwise, fall back to the global correlation_ID.
    current_corr_id = corrID if corrID is not None else correlation_ID
    corr_id_prefix = f'{current_corr_id} - ' if current_corr_id else ''

    logging.info(f'{corr_id_prefix}Function `add_two_numbers` called with num1={num1}, num2={num2}.')

    # Attempt to convert inputs to integers.
    logging.info(f'{corr_id_prefix}Attempting to convert inputs to integers.')
    try:
        num1_int = int(num1)
        num2_int = int(num2)
    except ValueError as e:
        # Log the specific conversion failure and then re-raise the error.
        logging.error(f'{corr_id_prefix}Conversion to integer failed for input(s) num1="{num1}" and num2="{num2}". Original error: {e}.')
        # Re-raise a ValueError with the specific error message requested in the problem description.
        raise ValueError("Invalid input. Please provide numbers.") from e

    # Calculate the sum using the successfully converted integer values.
    result = num1_int + num2_int
    logging.info(f'{corr_id_prefix}Calculation successful. Result: {result}.')

    # Return the result.
    return result


class TestAddTwoNumbers(unittest.TestCase):

    def setUp(self):
        # Capture logging output
        self.log_stream = io.StringIO()
        logging.basicConfig(level=logging.INFO, stream=self.log_stream, format='%(levelname)s:%(message)s')
        # Reset the logging handlers to avoid duplicates in subsequent tests
        for handler in logging.root.handlers[:]:
            logging.root.removeHandler(handler)
        logging.basicConfig(level=logging.INFO, stream=self.log_stream, format='%(levelname)s:%(message)s')


    def tearDown(self):
        # Clean up logging
        self.log_stream.close()
        # Restore default logging behavior (optional, but good practice)
        for handler in logging.root.handlers[:]:
            logging.root.removeHandler(handler)
        logging.basicConfig(level=logging.WARNING, stream=sys.stderr) # Set back to default or desired level

    def test_add_integers(self):
        """Test with valid integer inputs."""
        self.assertEqual(add_two_numbers(5, 3), 8)
        self.assertEqual(add_two_numbers(-1, 1), 0)
        self.assertEqual(add_two_numbers(0, 0), 0)

    def test_add_string_integers(self):
        """Test with valid string-represented integer inputs."""
        self.assertEqual(add_two_numbers("10", "20"), 30)
        self.assertEqual(add_two_numbers("-5", "5"), 0)
        self.assertEqual(add_two_numbers("0", "7"), 7)

    def test_add_mixed_inputs(self):
        """Test with mixed integer and string-represented integer inputs."""
        self.assertEqual(add_two_numbers(15, "5"), 20)
        self.assertEqual(add_two_numbers("3", 7), 10)

    def test_invalid_input_raises_value_error_with_specific_message(self):
        """
        Test that ValueError is raised with the specific fixed message
        for non-convertible inputs.
        """
        test_cases = [
            ("abc", 1),
            (1, "xyz"),
            ("hello", "world"),
            ("1.5", 2), # Floats as strings are not directly convertible to int without losing precision
            (None, 5), # NoneType
            (5, [1,2]) # List
        ]
        expected_error_message = "Invalid input. Please provide numbers."

        for num1, num2 in test_cases:
            with self.subTest(num1=num1, num2=num2):
                with self.assertRaisesRegex(ValueError, expected_error_message) as cm:
                    add_two_numbers(num1, num2)
                # Optionally, assert that the underlying cause is the original ValueError
                self.assertIsNotNone(cm.exception.__cause__)
                self.assertIsInstance(cm.exception.__cause__, ValueError)

    def test_logging_on_success(self):
        """Test that correct info logs are generated on successful execution."""
        add_two_numbers(1, 2, corrID="test_corr_id")
        log_output = self.log_stream.getvalue()
        self.assertIn("INFO:test_corr_id - Function `add_two_numbers` called with num1=1, num2=2.", log_output)
        self.assertIn("INFO:test_corr_id - Attempting to convert inputs to integers.", log_output)
        self.assertIn("INFO:test_corr_id - Calculation successful. Result: 3.", log_output)

    def test_logging_on_error(self):
        """Test that correct error log is generated on conversion failure."""
        with self.assertRaises(ValueError):
            add_two_numbers("bad", 2, corrID="error_test_corr_id")
        log_output = self.log_stream.getvalue()
        self.assertIn("ERROR:error_test_corr_id - Conversion to integer failed for input(s) num1=\"bad\" and num2=\"2\". Original error: invalid literal for int() with base 10: 'bad'.", log_output)


if __name__ == '__main__':
    unittest.main()
